Workbook
Name lstAnlieferung: Listen!$L$2:$L$5
Name lstBusinessType: Listen!$J$2:$J$4
Name lstClickType: Listen!$G$2:$G$3
Name lstFaktGebuehren: Listen!$M$2:$M$3
Name lstFaktLeasing: Listen!$B$2:$B$3
Name lstFakturierung: Listen!$C$2:$C$5
Name lstFCMaintenance: Listen!$R$2:$R$2
Name lstFCProjekt: Listen!$S$2:$S$3
Name lstFCSoftware: Listen!$Q$2:$Q$2
Name lstFleet: Listen!$I$2:$I$4
Name lstJaNein: Listen!$A$2:$A$3
Name lstKalkHW: Listen!$E$2:$E$5
Name lstKalkSW: Listen!$F$2:$F$5
Name lstLabelKontakt: Listen!$U$2:$U$5
Name lstLabelPauschale: Listen!$T$2:$T$5
Name lstLaufzeit: Listen!$D$2:$D$7
Name lstMehrscan: Listen!$P$2:$P$3
Name lstMehrseitenColor: Listen!$N$2:$N$3
Name lstMehrseitenSW: Listen!$O$2:$O$3
Name lstSLA: Listen!$H$2:$H$5
Name lstSLAType: Listen!$W$2:$W$41
Name lstSupportType: Listen!$V$2:$V$56
Name lstVertragsart: Listen!$K$2:$K$8
Name lstZaehler: Listen!$X$2:$X$20
Name tblZaehler: Listen!$X$2:$AB$20

Sheet Kalkulation
A1: Kalkulationstool | C1: Version: Q4 2025 rev. 1 | G1: 46274 | L1: 46274
C2: .
A3: Verkäufer : | D3: Verkäufer Nr.: | G3: Servicegebiet Code | I3: Kunden/CRM Nr. | L3: Hauptkontakt Nr. | N3: Navigationsbereich
L4: Offert Version: | M4: V-
A5: Kunde :
A6: Verrechnung :
A7: Standort :
A8: Instruktion : | L8: Verkaufschance Nr.
A9: Netzwerkintegration : | L9: Date: | M9: =TODAY() -> 46274
A10: Zählerversandart: | B10: ? | C10: =VLOOKUP($B$10,tblZaehler,3,FALSE) -> - | H10: =VLOOKUP($B$10,tblZaehler,4,FALSE) -> - | M10: =VLOOKUP($B$10,tblZaehler,5,FALSE) -> -
A11: =IF(OR($B$10="Autonomously",$B$10="Web-Portal manually",$B$10="List"),INDEX(lstLabelKontakt,1),"") | B11: =IF(OR($B$10="Autonomously",$B$10="Web-Portal manually",$B$10="List"),INDEX(lstLabelKontakt,2),"") | E11: =IF(OR($B$10="Autonomously",$B$10="Web-Portal manually",$B$10="List"),INDEX(lstLabelKontakt,3),"") | H11: =IF(OR($B$10="Autonomously",$B$10="Web-Portal manually",$B$10="List"),INDEX(lstLabelKontakt,4),"")
A14: Business Type | C14: FALSE | H14: =IF(J16=12,24,IF(J16=24,24/0.95,J16)) -> 48 | I14: Fakt. Leasing | J14: Vertragsdetails | L14: Fakturierungsperiode
A15: New New Business / Neukunde | E15: FALSE | G15: =IF(I16=1,1,IF(I16=3,1,IF(I16=4,1,0))) -> 0 | H15: FALSE | J15: Laufzeit | L15: Fakt. Pauschale | M15: Quartalsweise
A16: Normal | F16: FALSE | G16: 0.018914 | I16: 2 | J16: 48 | L16: Fakt. Mehrseiten | M16: Halbjährlich
A17: FALSE | B17: TRUE
A18: Details des alten Vertrages
A19: Modell | G19: Anzahl offene Mietraten - Monate | M19: 1
A20: Serien-Nr. | E20: Rabattsatz
A21: Vertrags-Enddatum | D21: FALSE | E21: 0 | G21: Miete (pro Monat) alter Vertrag ohne Service | M21: =IF(D21=TRUE,J19*J21*M19,0) -> 0
G23: Aufrechnung des alten Mietwertes | L23: FALSE
A25: Hardware | G25: Solutions -> Software/Hardware
A26: Modell - Beschreibung / Artikel | C26: Listenpreis | D26: Kalkulationsart | E26: CIF | G26: Beschreibung | I26: Listenpreis / LP | J26: Kalkulationsart | K26: CIF | L26: Netto VP | M26: Amortisation
C27: 2000 | D27: 0.6 | E27: =C27*D27 -> 1200 | G27: Total Listenpreis Software/Hardware | I27: ='Detail Solutions'!E39 -> 0 | K27: ='Detail Solutions'!G39 -> 0 | L27: ='Detail Solutions'!H39 -> 0 | M27: =IFERROR(ROUND(((K27/$K$31)*$M$31)*20,0)/20,"")
D28: 0.6 | E28: =C28*D28 -> 0 | J28: 0.7 | K28: =I28*J28 -> 0 | L28: =I28 -> 0 | M28: =IFERROR(ROUND(((K28/$K$31)*$M$31)*20,0)/20,"")
D29: 0.6 | E29: =C29*D29 -> 0 | I29: 0 | J29: 0.7 | K29: =I29*J29 -> 0 | L29: =I29 -> 0 | M29: =IFERROR(ROUND(((K29/$K$31)*$M$31)*20,0)/20,"")
D30: 0.6 | E30: =C30*D30 -> 0 | I30: 0 | J30: 0.7 | K30: =I30*J30 -> 0 | L30: =I30 -> 0 | M30: =IFERROR(ROUND(((K30/$K$31)*$M$31)*20,0)/20,"")
D31: 0.6 | E31: =C31*D31 -> 0 | G31: Total | I31: =SUM(I27:I30) -> 0 | K31: =SUM(K27:K30) -> 0 | M31: =ROUND(IF($I$16=2,L32/$J$16,IF($I$16=5,L32/$J$16,0))*20,0)/20 -> 0
D32: 0.6 | E32: =C32*D32 -> 0 | G32: Rabattsatz | H32: =IFERROR(1-(L32/I31),"") | I32: =L32-K31 -> 0 | K32: Netto Verkaufspreis | L32: =SUM(L27:L31) -> 0
D33: 0.6 | E33: =C33*D33 -> 0 | H33: Marge in % => | I33: =IFERROR(I32/L32,"")
D34: 0.6 | E34: =C34*D34 -> 0 | G34: Solutions -> Maintenance
D35: 0.6 | E35: =C35*D35 -> 0 | G35: Beschreibung | I35: Listenpreis / LP | J35: Kalkulationsart | K35: CIF | L35: Netto VP | M35: Amortisation
D36: 0.6 | E36: =C36*D36 -> 0 | G36: Total Listenpreis Software/Hardware | I36: ='Detail Solutions'!E57 -> 0 | K36: ='Detail Solutions'!G57 -> 0 | L36: ='Detail Solutions'!H57 -> 0 | M36: =IFERROR(ROUND(((K36/$K$38)*$M$39)*20,0)/20,"")
D37: 0.6 | E37: =C37*D37 -> 0 | I37: 0 | J37: 0.7 | K37: =I37*J37 -> 0 | L37: =I37 -> 0 | M37: =IFERROR(ROUND(((K37/$K$38)*$M$39)*20,0)/20,"")
D38: 0.6 | E38: =C38*D38 -> 0 | G38: Total | I38: =SUM(I36:I37) -> 0 | K38: =K37+K36 -> 0
D39: 0.6 | E39: =C39*D39 -> 0 | G39: Rabattsatz | H39: =IFERROR(1-(L39/I38),"") | I39: =L39-K38 -> 0 | K39: Netto Verkaufspreis | L39: =SUM(L36:L38) -> 0 | M39: =ROUND(IF($I$16=2,L39/$J$16,IF($I$16=5,L39/$J$16,0))*20,0)/20 -> 0
D40: 0.6 | E40: =C40*D40 -> 0 | G40: Maintenance in Servicepauschale | I40: Nein | J40: in Verkauf/Miete | L40: in Mt.Pauschale
D41: 0.6 | E41: =C41*D41 -> 0 | H41: Marge in % => | I41: =IFERROR(I39/L39,"") | J41: =IF(I40=INDEX(lstJaNein,2),L39,0) -> 0 | L41: =IF(I40=INDEX(lstJaNein,1),L39,0) -> 0
D42: 0.6 | E42: =C42*D42 -> 0
D43: 0.6 | E43: =C43*D43 -> 0 | G43: Solution -> Dienstleistungen (Consulting, Projektmanagement, Implementation, Vertiefte Instruktion)
D44: 0.6 | E44: =C44*D44 -> 0 | G44: Beschreibung | I44: Anzahl / Stunde | J44: Preis / Stunde | L44: Total | M44: Amortisation
...

Sheet Detail Solutions
A1: =Kalkulation!$A$1 -> Kalkulationstool | C1: =Kalkulation!C1 -> Version: Q4 2025 rev. 1 | D1: =Kalkulation!G1 -> 46274 | I1: =Kalkulation!$L$1 -> 46274
A3: Verkäufer : | B3: =Kalkulation!B3 -> 0 | C3: Verkäufer Nr.: | D3: =Kalkulation!E3 -> 0 | I3: Kontakt Nr. | J3: =Kalkulation!M3 -> 0 | K3: Navigationsbereich
A4: Servicegebiet Code | B4: =Kalkulation!H3 -> 0 | C4: Kunden Nr. | D4: =Kalkulation!J3 -> 0 | I4: Verkaufschance Nr. | J4: =Kalkulation!M8 -> 0
A5: Kunde : | B5: =Kalkulation!B5 -> 0 | C5: =Kalkulation!D5 -> 0 | D5: =Kalkulation!G5 -> 0 | E5: =Kalkulation!J5 -> 0
A6: Offert Version N°: | B6: =Kalkulation!M4 -> V- | I6: Date: | J6: =TODAY() -> 46274
A10: Name Enduser Kontakt KUNDE mit Adresse: | I10: Telefon:
A11: Email-Adresse: | I11: Mobile:
A12: Consultant - GRAPHAX
A13: Projekt mit folgendem Techniker vorbesprochen: (-> Falls keine Angabe, Disposition durch GSC): | G13: Wunsch Installationsdatum:
A14: Direktlieferung Lizenzen an (z.B. Kunde)
A15: Link Ablage Lösungsbeschreibung | G15: SLA Type :
A19: Solution -> Software-Lizenzen / Hardware
A20: Anzahl | B20: Art.-Nr. | C20: Bezeichnung | D20: Listenpreis pro Artikel | E20: Total Listenpreis | F20: Kalkulations-art | G20: CIF | H20: Netto Preis | I20: Amortisation | J20: Function Code
E21: =D21*A21 -> 0 | F21: 0.7 | G21: =E21*F21 -> 0 | H21: =E21 -> 0 | I21: =IFERROR(ROUND(((G21/Kalkulation!$K$31)*Kalkulation!$M$31)*20,0)/20,"") | J21: MIETESOFT
E22: =D22*A22 -> 0 | F22: 0.7 | G22: =E22*F22 -> 0 | H22: =E22 -> 0 | I22: =IFERROR(ROUND(((G22/Kalkulation!$K$31)*Kalkulation!$M$31)*20,0)/20,"") | J22: MIETESOFT
E23: =D23*A23 -> 0 | F23: 0.7 | G23: =E23*F23 -> 0 | H23: =E23 -> 0 | I23: =IFERROR(ROUND(((G23/Kalkulation!$K$31)*Kalkulation!$M$31)*20,0)/20,"") | J23: MIETESOFT
E24: =D24*A24 -> 0 | F24: 0.7 | G24: =E24*F24 -> 0 | H24: =E24 -> 0 | I24: =IFERROR(ROUND(((G24/Kalkulation!$K$31)*Kalkulation!$M$31)*20,0)/20,"") | J24: MIETESOFT
E25: =D25*A25 -> 0 | F25: 0.7 | G25: =E25*F25 -> 0 | H25: =E25 -> 0 | I25: =IFERROR(ROUND(((G25/Kalkulation!$K$31)*Kalkulation!$M$31)*20,0)/20,"") | J25: MIETESOFT
E26: =D26*A26 -> 0 | F26: 0.7 | G26: =E26*F26 -> 0 | H26: =E26 -> 0 | I26: =IFERROR(ROUND(((G26/Kalkulation!$K$31)*Kalkulation!$M$31)*20,0)/20,"") | J26: MIETESOFT
E27: =D27*A27 -> 0 | F27: 0.7 | G27: =E27*F27 -> 0 | H27: =E27 -> 0 | I27: =IFERROR(ROUND(((G27/Kalkulation!$K$31)*Kalkulation!$M$31)*20,0)/20,"") | J27: MIETESOFT
E28: =D28*A28 -> 0 | F28: 0.7 | G28: =E28*F28 -> 0 | H28: =E28 -> 0 | I28: =IFERROR(ROUND(((G28/Kalkulation!$K$31)*Kalkulation!$M$31)*20,0)/20,"") | J28: MIETESOFT
E29: =D29*A29 -> 0 | F29: 0.7 | G29: =E29*F29 -> 0 | H29: =E29 -> 0 | I29: =IFERROR(ROUND(((G29/Kalkulation!$K$31)*Kalkulation!$M$31)*20,0)/20,"") | J29: MIETESOFT
E30: =D30*A30 -> 0 | F30: 0.7 | G30: =E30*F30 -> 0 | H30: =E30 -> 0 | I30: =IFERROR(ROUND(((G30/Kalkulation!$K$31)*Kalkulation!$M$31)*20,0)/20,"") | J30: MIETESOFT
E31: =D31*A31 -> 0 | F31: 0.7 | G31: =E31*F31 -> 0 | H31: =E31 -> 0 | I31: =IFERROR(ROUND(((G31/Kalkulation!$K$31)*Kalkulation!$M$31)*20,0)/20,"") | J31: MIETESOFT
E32: =D32*A32 -> 0 | F32: 0.7 | G32: =E32*F32 -> 0 | H32: =E32 -> 0 | I32: =IFERROR(ROUND(((G32/Kalkulation!$K$31)*Kalkulation!$M$31)*20,0)/20,"") | J32: MIETESOFT
... E38: =D38*A38 -> 0 | F38: 0.7 | G38: =E38*F38 -> 0 | H38: =E38 -> 0 | I38: =IFERROR(ROUND(((G38/Kalkulation!$K$31)*Kalkulation!$M$31)*20,0)/20,"") | J38: MIETESOFT
D39: Total Software (Beiblatt Solutions) | E39: =SUM(E21:E38) -> 0 | G39: =SUM(G21:G38) -> 0 | H39: =SUM(H21:H38) -> 0
A41: Solution -> Maintenance
A42: Anzahl | B42: Art.-Nr. | C42: Bezeichnung | D42: Listenpreis pro Artikel | E42: Total Listenpreis | F42: Kalkulationsart | G42: CIF | H42: Netto Preis | I42: Amortisation | J42: Function Code
E43: =D43*A43 -> 0 | F43: 0.7 | G43: =E43*F43 -> 0 | H43: =E43 -> 0 | I43: =IFERROR(ROUND(((G43/Kalkulation!$K$38)*Kalkulation!$M$39)*20,0)/20,"") | J43: MIETESWM
E44: =D44*A44 -> 0 | F44: 0.7 | G44: =E44*F44 -> 0 | H44: =E44 -> 0 | I44: =IFERROR(ROUND(((G44/Kalkulation!$K$38)*Kalkulation!$M$39)*20,0)/20,"") | J44: MIETESWM
E45: =D45*A45 -> 0 | F45: 0.7 | G45: =E45*F45 -> 0 | H45: =E45 -> 0 | I45: =IFERROR(ROUND(((G45/Kalkulation!$K$38)*Kalkulation!$M$39)*20,0)/20,"") | J45: MIETESWM
E46: =D46*A46 -> 0 | F46: 0.7 | G46: =E46*F46 -> 0 | H46: =E46 -> 0 | I46: =IFERROR(ROUND(((G46/Kalkulation!$K$38)*Kalkulation!$M$39)*20,0)/20,"") | J46: MIETESWM
E47: =D47*A47 -> 0 | F47: 0.7 | G47: =E47*F47 -> 0 | H47: =E47 -> 0 | I47: =IFERROR(ROUND(((G47/Kalkulation!$K$38)*Kalkulation!$M$39)*20,0)/20,"") | J47: MIETESWM
E48: =D48*A48 -> 0 | F48: 0.7 | G48: =E48*F48 -> 0 | H48: =E48 -> 0 | I48: =IFERROR(ROUND(((G48/Kalkulation!$K$38)*Kalkulation!$M$39)*20,0)/20,"") | J48: MIETESWM
E49: =D49*A49 -> 0 | F49: 0.7 | G49: =E49*F49 -> 0 | H49: =E49 -> 0 | I49: =IFERROR(ROUND(((G49/Kalkulation!$K$38)*Kalkulation!$M$39)*20,0)/20,"") | J49: MIETESWM
E50: =D50*A50 -> 0 | F50: 0.7 | G50: =E50*F50 -> 0 | H50: =E50 -> 0 | I50: =IFERROR(ROUND(((G50/Kalkulation!$K$38)*Kalkulation!$M$39)*20,0)/20,"") | J50: MIETESWM
E51: =D51*A51 -> 0 | F51: 0.7 | G51: =E51*F51 -> 0 | H51: =E51 -> 0 | I51: =IFERROR(ROUND(((G51/Kalkulation!$K$38)*Kalkulation!$M$39)*20,0)/20,"") | J51: MIETESWM
E52: =D52*A52 -> 0 | F52: 0.7 | G52: =E52*F52 -> 0 | H52: =E52 -> 0 | I52: =IFERROR(ROUND(((G52/Kalkulation!$K$38)*Kalkulation!$M$39)*20,0)/20,"") | J52: MIETESWM
E53: =D53*A53 -> 0 | F53: 0.7 | G53: =E53*F53 -> 0 | H53: =E53 -> 0 | I53: =IFERROR(ROUND(((G53/Kalkulation!$K$38)*Kalkulation!$M$39)*20,0)/20,"") | J53: MIETESWM
...

Sheet GE-Leasing
A1: Kalkulationsfaktoren für ZKB-Leasing | H1: Navigationsbereich
B4: Version: Q4 2025 rev. 1 | D4: Gültig ab 09.09.2026 | G4: letzte Aktualisierung: 09.09.2026
B7: Quartal
B8: Wert | C8: 24 | D8: 36 | E8: 48 | F8: 60
B9: Ab 2'000 | C9: =C18*3 -> 0.129651 | D9: =D18*3 -> 0.0891 | E9: =E18*3 -> 0.06885 | F9: =F18*3 -> 0.056718
B10: Ab 10'000 | C10: =C19*3 -> 0.129651 | D10: =D19*3 -> 0.0891 | E10: =E19*3 -> 0.06885 | F10: =F19*3 -> 0.056718
B11: Ab 20'000 | C11: =C20*3 -> 0.129651 | D11: =D20*3 -> 0.0891 | E11: =E20*3 -> 0.06885 | F11: =F20*3 -> 0.056718
B12: Ab 30'000 | C12: =C21*3 -> 0.129651 | D12: =D21*3 -> 0.0891 | E12: =E21*3 -> 0.06885 | F12: =F21*3 -> 0.056718
B13: Ab 50'000 | C13: =C22*3 -> 0.129285 | D13: =D22*3 -> 0.088722 | E13: =E22*3 -> 0.068457 | F13: =F22*3 -> 0.056325
B14: Ab 100'000 | C14: 0.12945 | D14: 0.0888 | E14: 0.06855 | F14: 0.0564
B16: Monatlich
B17: Valeur | C17: 24 | D17: 36 | E17: 48 | F17: 60
B18: Ab 2'000 | C18: 0.043217 | D18: 0.0297 | E18: 0.02295 | F18: 0.018906
B19: Ab 10'000 | C19: 0.043217 | D19: 0.0297 | E19: 0.02295 | F19: 0.018906
B20: Ab 20'000 | C20: 0.043217 | D20: 0.0297 | E20: 0.02295 | F20: 0.018906
B21: Ab 30'000 | C21: 0.043217 | D21: 0.0297 | E21: 0.02295 | F21: 0.018906
B22: Ab 50'000 | C22: 0.043095 | D22: 0.029574 | E22: 0.022819 | F22: 0.018775
B23: Ab 100'000 | C23: 0.04315 | D23: 0.0296 | E23: 0.02285 | F23: 0.0188
B26: Bei Beendigung des Leasingvertrags geht das Leasingobjekt an den Lieferanten Graphax AG zurück.
B28: Bearbeitungsgebühr:
B29: Nachfolgende Bearbeitungsgebühr wird dem Leasingnehmer mit der 1. Leasing-Rate verrechnet (exkl. MWSt) | F29: 100
B31: Pro Memoria: | C31: Ein Leasingvertrag setzt in jedem Fall eine Bonitätsabklärung seitens Leasinggeber voraus.
C32: Die Abklärungen durch die Leasingfirma ist frühzeitig einzuleiten.
B36: Beispiel für die Berechnung einer Leasingzahlung
B38: KM bizhub C280 | C38: Listenpreis | D38: 10500
C39: ./. 10% Rabatt | D39: =SUM(D38*0.1) -> 1050
C41: Netto Verkaufspreis | D41: =SUM(D38-D39) -> 9450
B43: 48 Monate (Quartal) | C43: =E9 -> 0.06885 | D43: =SUM(D41*E9) -> 650.6325
B47: Graphax AG - Private Data | F47: Seite 1 von 1

Sheet Miete Graphax
A1: Kalkulationsfaktoren für Graphax Miete | J1: Navigationsbereich
B4: Version: Q4 2025 rev. 1 | E4: Gültig ab 09.09.2026 | G4: letzte Aktualisierung: 09.09.2026
C7: Faktor offen – noch zu definieren
B8: Wert | C8: 12 Monate - Verlängerung | D8: 72 | E8: 24 | F8: 36 | G8: 48 | H8: 60
B9: Ab 2'000 | D9: 0.0161 | E9: 0.044999593 | F9: 0.031106218 | G9: 0.023946245 | H9: 0.019990463
B10: Ab 10'000 | D10: 0.01606 | E10: 0.044546251 | F10: 0.030740117 | G10: 0.023668859 | H10: 0.019706974
B11: Ab 20'000 | D11: 0.01601 | E11: 0.044095656 | F11: 0.030376648 | G11: 0.023393443 | H11: 0.019425936
B12: Ab 50'000 | D12: 0.01597 | E12: 0.043647812 | F12: 0.030015816 | G12: 0.023120001 | H12: 0.019147353
B13: Ab 100'000 | D13: 0.01592 | E13: 0.043202722 | F13: 0.029657625 | G13: 0.022848538 | H13: 0.018871234
B14: Ab 250'000 | D14: 0.01587 | E14: 0.042760392 | F14: 0.02930208 | G14: 0.022579055 | H14: 0.018597582
C15: =IF(Kalkulation!$C$62>=250000,C14,IF(Kalkulation!$C$62>=100000,C13,IF(Kalkulation!$C$62>=50000,C12,IF(Kalkulation!$C$62>=20000,C11,IF(Kalkulation!$C$62>=10000,C10,C9))))) -> 0 | D15: =IF(Kalkulation!$C$62>=250000,D14,IF(Kalkulation!$C$62>=100000,D13,IF(Kalkulation!$C$62>=50000,D12,IF(Kalkulation!$C$62>=20000,D11,IF(Kalkulation!$C$62>=10000,D10,D9))))) -> 0.0161 | E15: =IF(Kalkulation!$C$62>=250000,E14,IF(Kalkulation!$C$62>=100000,E13,IF(Kalkulation!$C$62>=50000,E12,IF(Kalkulation!$C$62>=20000,E11,IF(Kalkulation!$C$62>=10000,E10,E9))))) -> 0.044999593 | F15: =IF(Kalkulation!$C$62>=250000,F14,IF(Kalkulation!$C$62>=100000,F13,IF(Kalkulation!$C$62>=50000,F12,IF(Kalkulation!$C$62>=20000,F11,IF(Kalkulation!$C$62>=10000,F10,F9))))) -> 0.031106218 | G15: =IF(Kalkulation!$C$62>=250000,G14,IF(Kalkulation!$C$62>=100000,G13,IF(Kalkulation!$C$62>=50000,G12,IF(Kalkulation!$C$62>=20000,G11,IF(Kalkulation!$C$62>=10000,G10,G9))))) -> 0.023946245 | H15: =IF(Kalkulation!$C$62>=250000,H14,IF(Kalkulation!$C$62>=100000,H13,IF(Kalkulation!$C$62>=50000,H12,IF(Kalkulation!$C$62>=20000,H11,IF(Kalkulation!$C$62>=10000,H10,H9))))) -> 0.019990463
B17: Bei der Miete wird keine Amortisation berechnet
B19: Möchte ein Kunde sein Mietgerät aus einem laufenden Mietvertrag käuflich erwerben nehmen Sie bitte das Verkaufsreglement Pkt. 5.5 zur Hilfe.
B21: Bearbeitungsgebühr:
B22: Die Bearbeitungsgebühr wird dem Vertragsnehmer verrechnet | H22: Kostenlos
B24: Pro Memoria:
B29: Beispiel zur Berechnung der monatlichen Mietrate
B31: Konica Minolta bizhub C360i | E31: Listenpreis | F31: 13680
E32: ./. 5 % Rabatt | F32: =SUM(F31*0.05) -> 684
E34: Netto Verkaufspreis | F34: =SUM(F31-F32) -> 12996
B36: Miete 48 Monate | E36: =G10 -> 0.023668859 | F36: =E36*F34 -> 307.60049
B37: Service Grundpauschale | F37: 50
B38: 1'000 Seiten à 15 Rp. | F38: 150
B40: Monatliche Mietrate inkl. 1'000 Seiten | F40: =SUM(F36:F39) -> 507.60049
B43: Berechnung bei käuflicher Übernahme eines Mietgegenstandes
B45: Miervertrag für bizhub C360 | E45: 48 | F45: =$F$36 -> 307.60049 | G45: =SUM(E45*F45) -> 14764.823
B46: bereits bezahlte Mietraten | E46: 45 | F46: =$F$36 -> 307.60049 | G46: =SUM(E46*F46) -> 13842.022
B47: ausstehende Mietraten | E47: 3 | F47: =$F$36 -> 307.60049 | G47: =SUM(E47*F47) -> 922.80146
B48: 5% von Netto Verkaufspreis | F48: =F34*5% -> 649.8 | G48: =F48 -> 649.8
B49: Totalbetrag bei Übernahme | G49: =SUM(G47:G48) -> 1572.6015
B55: Graphax AG - Private Data | E55: Marketing | H55: Seite 1 von 1

Sheet Listen
A1: lstJaNein | B1: lstFaktLeasing | C1: lstFakturierung | D1: lstLaufzeit | E1: lstKalkHW | F1: lstKalkSW | G1: lstClickType | H1: lstSLA | I1: lstFleet | J1: lstBusinessType | K1: lstVertragsart | L1: lstAnlieferung | M1: lstFaktGebuehren | N1: lstMehrseitenColor | O1: lstMehrseitenSW | P1: lstMehrscan | Q1: lstFCSoftware | R1: lstFCMaintenance | S1: lstFCProjekt | T1: lstLabelPauschale | U1: lstLabelKontakt | V1: lstSupportType | W1: lstSLAType | X1: Zählerversandart (tblZaehler) | Y1: Comm.Type SA | Z1: Beschreibung | AA1: Instruktionen: Artikel & zusätzliche Aufträge | AB1: Counter Correspondant Type
A2: Ja | B2: Monatlich | C2: Monatlich | D2: 12 | E2: 0.6 | F2: 0.7 | G2: A3 = A4 | H2: Basic - CHF 0.00 | I2: 6010 Fleet Service Level Basic | J2: Exchange / Austausch | K2: Normal | L2: Normal | M2: Verdeckt | N2: Mehrseitenpreis color - CHF : | O2: Mehrseitenpreis s/w - CHF : | P2: Mehrscanpreis - CHF : | Q2: MIETESOFT | R2: MIETESWM | S2: IMPLTRAI | T2: Total Verkaufspreis | U2: Kontaktdaten: | V2: AARGAU | W2: AUTOSTORE BASIC | X2: ? | Y2: - | Z2: - | AA2: - | AB2: -
A3: Nein | B3: Quartalsweise | C3: Quartalsweise | D3: 24 | E3: 1 | F3: 1 | G3: A3 = 2 * A4 | H3: Basic Plus - CHF 15.00 | I3: 6020 Fleet Service Level Progress | J3: New Business / Neuplatzierung | K3: Umwandlung | L3: Treppe | M3: Offen gem. Offerte | N3: Alle Farbseiten - CHF : | O3: Alle s/w-Seiten - CHF : | P3: Alle Scan - CHF : | S3: CONSPRES | T3: Mietpauschale pro Monat (ohne Service) | U3: Name? | V3: AMRABATT | W3: AVESCO EQUITRAC | X3: CSRC DCA | Y3: DCA | Z3: CS Remote DCA Integration | AA3: CSRCDCA | AB3: Remote
C4: Halbjährlich | D4: 36 | E4: 0.25 | F4: 0.5 | H4: Premium - CHF 50.00 | I4: 6030 Fleet Service Level Analysis | J4: New New Business / Neukunde | K4: Verlängerung | L4: Trag-Equipe | T4: Leasingpauschale pro Monat (ohne Service) | U4: Telefon? | V4: AMTAI | W4: BLUE BASIC | X4: CSRC DCA&SW | Y4: DCA | Z4: CS Remote DCA Integration mit Software Installation | AA4: CSRCDCA & zusätzlich Checkliste IDQM und sep. Auftrag für Software "DCASWI" | AB4: Remote
C5: Jährlich | D5: 48 | E5: 0.35 | F5: 0.3 | H5: Professional Printing - CHF 0.00 | K5: Vorzeitige Vertragsauflösung | L5: Spezialtransport | T5: Monatspauschale Total | U5: Email? | V5: ANLIKER | W5: CHRONOSCAN ADV BAS + | X5: CSRC DCAGBS | Y5: DCA | Z5: CS Remote DCA Integration for GBS Kunden | AA5: CSRCDCAGBS | AB5: Remote
D6: 60 | K6: Kauf aus Miete | V6: BALGRIST | W6: CHRONOSCAN ADV BASIC | X6: CSRC FAX | Y6: FAX | Z6: CS Remote Fax Integration | AA6: CSRCFAX | AB6: Remote
D7: 72 | K7: Kauf aus Leasing | V7: BELLINZONA | W7: CHRONOSCAN ADV PREM | X7: CSRC Internet HTTPS | Y7: HTTP | Z7: CS Remote Care Internet (https) Integration | AA7: CSRCHTTP | AB7: Remote
K8: Eigenprodukt/Fremdprodukt | V8: BJB | W8: CHRONOSCAN ENT BAS + | X8: CSRC PRFL | Y8: Pfleet | Z8: CS Remote Print Fleet Integration | AA8: CSRCPRFL | AB8: Remote
V9: BURGDORF | W9: CHRONOSCAN ENT BASIC | X9: CSRC SITA | Y9: SiteAudit | Z9: CS Remote Site Audit Integration | AA9: CSRCSITA | AB9: Remote
V10: CADES | W10: CHRONOSCAN ENT PREM | X10: CSRC GPRS | Y10: GPRS | Z10: CS Remote mit Modem Integration | AA10: CSRCGPRS | AB10: Remote
V11: CAJU | W11: CON.2 PDF BASIC | X11: Fleet TI Tool | Y11: -- | Z11: TI Tool Fleet Management Integration | AA11: 6010 / 6020 | AB11: Web-Portal automat.
V12: CHANNEL GRAPHAX | W12: CON.2 PDF BASIC PLUS | X12: Fleet TI Tool & SW | Y12: -- | Z12: TI Tool Fleet Management Integration mit Software Installation (PM) | AA12: 6010 / 6020 & zusätzlich Checkliste TI Tool und sep. Auftrag / Installadresse für Software PrintMonitor | AB12: Web-Portal automat.
V13: COOP | W13: CON.2 PDF PREMIUM | X13: Fleet TI Tool & Plug | Y13: -- | Z13: TI Tool Fleet Management Integration mit Plug2 Installation | AA13: 6010 / 6020 & zusätzlich Checkliste TI Tool und sep. Auftrag / Installadresse für Plug2 "SPLUG" | AB13: Web-Portal automat.
V14: CX PRINT | W14: DISPATCHER PHOENIX | X14: Web-Portal manually | Y14: -- | Z14: Zählermeldung durch Kunde via Portal | AA14: Kontaktdaten für Zähler unbedingt eingeben: Name, Tel.-Nummer, Email | AB14: Web-Portal manually
V15: CX2526 | W15: EOP BASIC
V16: DAL | W16: EPPO BASIC
V17: DERTOUR | W17: EQUITRAC BASIC
V18: EKZ | W18: GDX (ECM/DMS)
V19: EMIL FREY AG | W19: INEPRO BASIC | X19: Autonomously | Y19: Ausnahmen | Z19: Zähler nach individuelle Vereinbarung mit dem Kunden | AA19: Kontaktdaten für Zähler unbedingt eingeben: Name, Tel.-Nummer, Email | AB19: Autonomously
V20: ERNE | W20: ITS SERVER ONLY | X20: List | Y20: Ausnahmen | Z20: Zählermeldung via Kundenliste | AA20: Kontaktdaten für Zähler unbedingt eingeben: Name, Tel.-Nummer, Email | AB20: List
V21: EVAM | W21: ITSBASIC
V22: GENEVE | W22: ITSBASIC+
V23: GHG | W23: ITSPREMIUM
V24: GMAS | W24: ITSPREMIUM_PLUS
V25: GPH15A25_15M | W25: KANTON AARGAU SW
V26: GRAFOSA | W26: PFISTER SW
V27: HEILSARMEE | W27: PHOENIX SW
V28: HOSPICE GÉNÉRAL | W28: POLYRIGHT POS
V29: HOTELPLAN | W29: POLYRIGHT PREMIUM
V30: ISAB | W30: POLYRIGHT STANDARD
V31: KAIO | W31: PP SW BASIC
V32: KALAIDOS | W32: PSES BASIC
... V41: POENINA | W41: UNITY BASIC
V42: PPIPS
V43: PSAG_GOSSAU
V44: PUBLIC SECTOR
V45: SCHENKER
V46: SPIEZ
V47: SPSH
V48: TERTIANUM
...
